<?xml version="1.0" ?>
<!-- UR3e + OnRobot RG2 Gripper - Flattened URDF for Unity URDF-Importer -->
<!-- Based on ur3e.urdf + onrobot_rg2 xacro from UOsaka-Harada-Laboratory/onrobot -->
<robot name="ur3e_rg2">

  <!-- ==================== UR3e Transmissions ==================== -->
  <transmission name="shoulder_pan_trans">
    <type>transmission_interface/SimpleTransmission</type>
    <joint name="shoulder_pan_joint">
      <hardwareInterface>hardware_interface/PositionJointInterface</hardwareInterface>
    </joint>
    <actuator name="shoulder_pan_motor">
      <mechanicalReduction>1</mechanicalReduction>
    </actuator>
  </transmission>
  <transmission name="shoulder_lift_trans">
    <type>transmission_interface/SimpleTransmission</type>
    <joint name="shoulder_lift_joint">
      <hardwareInterface>hardware_interface/PositionJointInterface</hardwareInterface>
    </joint>
    <actuator name="shoulder_lift_motor">
      <mechanicalReduction>1</mechanicalReduction>
    </actuator>
  </transmission>
  <transmission name="elbow_trans">
    <type>transmission_interface/SimpleTransmission</type>
    <joint name="elbow_joint">
      <hardwareInterface>hardware_interface/PositionJointInterface</hardwareInterface>
    </joint>
    <actuator name="elbow_motor">
      <mechanicalReduction>1</mechanicalReduction>
    </actuator>
  </transmission>
  <transmission name="wrist_1_trans">
    <type>transmission_interface/SimpleTransmission</type>
    <joint name="wrist_1_joint">
      <hardwareInterface>hardware_interface/PositionJointInterface</hardwareInterface>
    </joint>
    <actuator name="wrist_1_motor">
      <mechanicalReduction>1</mechanicalReduction>
    </actuator>
  </transmission>
  <transmission name="wrist_2_trans">
    <type>transmission_interface/SimpleTransmission</type>
    <joint name="wrist_2_joint">
      <hardwareInterface>hardware_interface/PositionJointInterface</hardwareInterface>
    </joint>
    <actuator name="wrist_2_motor">
      <mechanicalReduction>1</mechanicalReduction>
    </actuator>
  </transmission>
  <transmission name="wrist_3_trans">
    <type>transmission_interface/SimpleTransmission</type>
    <joint name="wrist_3_joint">
      <hardwareInterface>hardware_interface/PositionJointInterface</hardwareInterface>
    </joint>
    <actuator name="wrist_3_motor">
      <mechanicalReduction>1</mechanicalReduction>
    </actuator>
  </transmission>

  <!-- ==================== UR3e Links ==================== -->
  <link name="base_link"/>
  <link name="base_link_inertia">
    <visual>
      <origin rpy="0 0 3.141592653589793" xyz="0 0 0"/>
      <geometry>
        <mesh filename="package://ur_description/meshes/ur3e/visual/base.dae"/>
      </geometry>
      <material name="LightGrey">
        <color rgba="0.7 0.7 0.7 1.0"/>
      </material>
    </visual>
    <collision>
      <origin rpy="0 0 3.141592653589793" xyz="0 0 0"/>
      <geometry>
        <mesh filename="package://ur_description/meshes/ur3e/collision/base.stl"/>
      </geometry>
    </collision>
    <inertial>
      <mass value="2.0"/>
      <origin rpy="0 0 0" xyz="0 0 0"/>
      <inertia ixx="0.0030531654454" ixy="0.0" ixz="0.0" iyy="0.0030531654454" iyz="0.0" izz="0.005625"/>
    </inertial>
  </link>
  <link name="shoulder_link">
    <visual>
      <origin rpy="0 0 3.141592653589793" xyz="0 0 0"/>
      <geometry>
        <mesh filename="package://ur_description/meshes/ur3e/visual/shoulder.dae"/>
      </geometry>
      <material name="LightGrey">
        <color rgba="0.7 0.7 0.7 1.0"/>
      </material>
    </visual>
    <collision>
      <origin rpy="0 0 3.141592653589793" xyz="0 0 0"/>
      <geometry>
        <mesh filename="package://ur_description/meshes/ur3e/collision/shoulder.stl"/>
      </geometry>
    </collision>
    <inertial>
      <mass value="2.0"/>
      <origin rpy="0 0 0" xyz="0 0 0"/>
      <inertia ixx="0.008093163429399999" ixy="0.0" ixz="0.0" iyy="0.008093163429399999" iyz="0.0" izz="0.005625"/>
    </inertial>
  </link>
  <link name="upper_arm_link">
    <visual>
      <origin rpy="1.5707963267948966 0 -1.5707963267948966" xyz="0 0 0.12"/>
      <geometry>
        <mesh filename="package://ur_description/meshes/ur3e/visual/upperarm.dae"/>
      </geometry>
      <material name="LightGrey">
        <color rgba="0.7 0.7 0.7 1.0"/>
      </material>
    </visual>
    <collision>
      <origin rpy="1.5707963267948966 0 -1.5707963267948966" xyz="0 0 0.12"/>
      <geometry>
        <mesh filename="package://ur_description/meshes/ur3e/collision/upperarm.stl"/>
      </geometry>
    </collision>
    <inertial>
      <mass value="3.42"/>
      <origin rpy="0 1.5707963267948966 0" xyz="-0.121825 0.0 0.12"/>
      <inertia ixx="0.021728483221103233" ixy="0.0" ixz="0.0" iyy="0.021728483221103233" iyz="0.0" izz="0.00961875"/>
    </inertial>
  </link>
  <link name="forearm_link">
    <visual>
      <origin rpy="1.5707963267948966 0 -1.5707963267948966" xyz="0 0 0.027"/>
      <geometry>
        <mesh filename="package://ur_description/meshes/ur3e/visual/forearm.dae"/>
      </geometry>
      <material name="LightGrey">
        <color rgba="0.7 0.7 0.7 1.0"/>
      </material>
    </visual>
    <collision>
      <origin rpy="1.5707963267948966 0 -1.5707963267948966" xyz="0 0 0.027"/>
      <geometry>
        <mesh filename="package://ur_description/meshes/ur3e/collision/forearm.stl"/>
      </geometry>
    </collision>
    <inertial>
      <mass value="1.26"/>
      <origin rpy="0 1.5707963267948966 0" xyz="-0.1066 0.0 0.027"/>
      <inertia ixx="0.0065445675821719194" ixy="0.0" ixz="0.0" iyy="0.0065445675821719194" iyz="0.0" izz="0.00354375"/>
    </inertial>
  </link>
  <link name="wrist_1_link">
    <visual>
      <origin rpy="1.5707963267948966 0 0" xyz="0 0 -0.104"/>
      <geometry>
        <mesh filename="package://ur_description/meshes/ur3e/visual/wrist1.dae"/>
      </geometry>
      <material name="LightGrey">
        <color rgba="0.7 0.7 0.7 1.0"/>
      </material>
    </visual>
    <collision>
      <origin rpy="1.5707963267948966 0 0" xyz="0 0 -0.104"/>
      <geometry>
        <mesh filename="package://ur_description/meshes/ur3e/collision/wrist1.stl"/>
      </geometry>
    </collision>
    <inertial>
      <mass value="0.8"/>
      <origin rpy="0 0 0" xyz="0 0 0"/>
      <inertia ixx="0.002084999166" ixy="0.0" ixz="0.0" iyy="0.002084999166" iyz="0.0" izz="0.00225"/>
    </inertial>
  </link>
  <link name="wrist_2_link">
    <visual>
      <origin rpy="0 0 0" xyz="0 0 -0.08535"/>
      <geometry>
        <mesh filename="package://ur_description/meshes/ur3e/visual/wrist2.dae"/>
      </geometry>
      <material name="LightGrey">
        <color rgba="0.7 0.7 0.7 1.0"/>
      </material>
    </visual>
    <collision>
      <origin rpy="0 0 0" xyz="0 0 -0.08535"/>
      <geometry>
        <mesh filename="package://ur_description/meshes/ur3e/collision/wrist2.stl"/>
      </geometry>
    </collision>
    <inertial>
      <mass value="0.8"/>
      <origin rpy="0 0 0" xyz="0 0 0"/>
      <inertia ixx="0.002084999166" ixy="0.0" ixz="0.0" iyy="0.002084999166" iyz="0.0" izz="0.00225"/>
    </inertial>
  </link>
  <link name="wrist_3_link">
    <visual>
      <origin rpy="1.5707963267948966 0 0" xyz="0 0 -0.0921"/>
      <geometry>
        <mesh filename="package://ur_description/meshes/ur3e/visual/wrist3.dae"/>
      </geometry>
      <material name="LightGrey">
        <color rgba="0.7 0.7 0.7 1.0"/>
      </material>
    </visual>
    <collision>
      <origin rpy="1.5707963267948966 0 0" xyz="0 0 -0.0921"/>
      <geometry>
        <mesh filename="package://ur_description/meshes/ur3e/collision/wrist3.stl"/>
      </geometry>
    </collision>
    <inertial>
      <mass value="0.35"/>
      <origin rpy="0 0 0" xyz="0.0 0.0 -0.02"/>
      <inertia ixx="0.00013626661215999998" ixy="0.0" ixz="0.0" iyy="0.00013626661215999998" iyz="0.0" izz="0.0001792"/>
    </inertial>
  </link>

  <!-- ==================== UR3e Joints ==================== -->
  <joint name="base_link-base_link_inertia" type="fixed">
    <parent link="base_link"/>
    <child link="base_link_inertia"/>
    <origin rpy="0 0 3.141592653589793" xyz="0 0 0"/>
  </joint>
  <joint name="shoulder_pan_joint" type="revolute">
    <parent link="base_link_inertia"/>
    <child link="shoulder_link"/>
    <origin rpy="0 0 0" xyz="0 0 0.15185"/>
    <axis xyz="0 0 1"/>
    <limit effort="56.0" lower="-6.283185307179586" upper="6.283185307179586" velocity="3.141592653589793"/>
    <dynamics damping="0" friction="0"/>
  </joint>
  <joint name="shoulder_lift_joint" type="revolute">
    <parent link="shoulder_link"/>
    <child link="upper_arm_link"/>
    <origin rpy="1.570796327 0 0" xyz="0 0 0"/>
    <axis xyz="0 0 1"/>
    <limit effort="56.0" lower="-6.283185307179586" upper="6.283185307179586" velocity="3.141592653589793"/>
    <dynamics damping="0" friction="0"/>
  </joint>
  <joint name="elbow_joint" type="revolute">
    <parent link="upper_arm_link"/>
    <child link="forearm_link"/>
    <origin rpy="0 0 0" xyz="-0.24355 0 0"/>
    <axis xyz="0 0 1"/>
    <limit effort="28.0" lower="-3.141592653589793" upper="3.141592653589793" velocity="3.141592653589793"/>
    <dynamics damping="0" friction="0"/>
  </joint>
  <joint name="wrist_1_joint" type="revolute">
    <parent link="forearm_link"/>
    <child link="wrist_1_link"/>
    <origin rpy="0 0 0" xyz="-0.2132 0 0.13105"/>
    <axis xyz="0 0 1"/>
    <limit effort="12.0" lower="-6.283185307179586" upper="6.283185307179586" velocity="6.283185307179586"/>
    <dynamics damping="0" friction="0"/>
  </joint>
  <joint name="wrist_2_joint" type="revolute">
    <parent link="wrist_1_link"/>
    <child link="wrist_2_link"/>
    <origin rpy="1.570796327 0 0" xyz="0 -0.08535 0"/>
    <axis xyz="0 0 1"/>
    <limit effort="12.0" lower="-6.283185307179586" upper="6.283185307179586" velocity="6.283185307179586"/>
    <dynamics damping="0" friction="0"/>
  </joint>
  <joint name="wrist_3_joint" type="revolute">
    <parent link="wrist_2_link"/>
    <child link="wrist_3_link"/>
    <origin rpy="1.570796326589793 3.141592653589793 3.141592653589793" xyz="0 0.0921 0"/>
    <axis xyz="0 0 1"/>
    <limit effort="12.0" lower="-6.283185307179586" upper="6.283185307179586" velocity="6.283185307179586"/>
    <dynamics damping="0" friction="0"/>
  </joint>

  <!-- ROS-Industrial 'base' frame -->
  <link name="base"/>
  <joint name="base_link-base_fixed_joint" type="fixed">
    <origin rpy="0 0 3.141592653589793" xyz="0 0 0"/>
    <parent link="base_link"/>
    <child link="base"/>
  </joint>

  <!-- ROS-Industrial 'flange' frame: attachment point for EEF models -->
  <link name="flange"/>
  <joint name="wrist_3-flange" type="fixed">
    <parent link="wrist_3_link"/>
    <child link="flange"/>
    <origin rpy="0 -1.5707963267948966 -1.5707963267948966" xyz="0 0 0"/>
  </joint>

  <!-- ROS-Industrial 'tool0' frame: all-zeros tool frame -->
  <link name="tool0"/>
  <joint name="flange-tool0" type="fixed">
    <origin rpy="1.5707963267948966 0 1.5707963267948966" xyz="0 0 0"/>
    <parent link="flange"/>
    <child link="tool0"/>
  </joint>

  <!-- ==================== OnRobot RG2 Gripper ==================== -->
  <!-- Attached to tool0 via fixed joint -->

  <!-- Gripper base link -->
  <link name="onrobot_rg2_base_link">
    <inertial>
      <origin xyz="0.0 0.0 0.0" rpy="0 0 0"/>
      <mass value="0.7"/>
      <inertia ixx="1.0E-03" ixy="1.0E-06" ixz="1.0E-06" iyy="1.0E-03" iyz="1.0E-06" izz="1.0E-03"/>
    </inertial>
    <visual>
      <origin xyz="0 0 0" rpy="0 0 0"/>
      <geometry>
        <mesh filename="package://onrobot_rg2/visual/base_link_visual.stl"/>
      </geometry>
      <material name="GripperGrey">
        <color rgba="0.8 0.8 0.8 1"/>
      </material>
    </visual>
    <collision>
      <origin xyz="0 0 0" rpy="0 0 0"/>
      <geometry>
        <mesh filename="package://onrobot_rg2/collision/base_link.stl"/>
      </geometry>
    </collision>
  </link>

  <!-- Attach gripper to tool0 -->
  <joint name="tool0-rg2_base" type="fixed">
    <parent link="tool0"/>
    <child link="onrobot_rg2_base_link"/>
    <origin xyz="0 0 0" rpy="0 0 0"/>
  </joint>

  <!-- ===== Left finger ===== -->

  <!-- Left outer knuckle -->
  <link name="left_outer_knuckle">
    <inertial>
      <origin xyz="0.0 0.0 0.0" rpy="0 0 0"/>
      <mass value="0.05"/>
      <inertia ixx="1.0E-03" ixy="1.0E-06" ixz="1.0E-06" iyy="1.0E-03" iyz="1.0E-06" izz="1.0E-03"/>
    </inertial>
    <visual>
      <origin xyz="0 0 0" rpy="0 0 0"/>
      <geometry>
        <mesh filename="package://onrobot_rg2/visual/outer_knuckle_visual.stl"/>
      </geometry>
      <material name="GripperGrey">
        <color rgba="0.8 0.8 0.8 1"/>
      </material>
    </visual>
    <collision>
      <origin xyz="0 0 0" rpy="0 0 0"/>
      <geometry>
        <mesh filename="package://onrobot_rg2/collision/outer_knuckle.stl"/>
      </geometry>
    </collision>
  </link>

  <!-- Left inner knuckle -->
  <link name="left_inner_knuckle">
    <inertial>
      <origin xyz="0.0 0.0 0.0" rpy="0 0 0"/>
      <mass value="0.05"/>
      <inertia ixx="1.0E-03" ixy="1.0E-06" ixz="1.0E-06" iyy="1.0E-03" iyz="1.0E-06" izz="1.0E-03"/>
    </inertial>
    <visual>
      <origin xyz="0 0 0" rpy="0 0 0"/>
      <geometry>
        <mesh filename="package://onrobot_rg2/visual/inner_knuckle_visual.stl"/>
      </geometry>
      <material name="GripperGrey">
        <color rgba="0.8 0.8 0.8 1"/>
      </material>
    </visual>
    <collision>
      <origin xyz="0 0 0" rpy="0 0 0"/>
      <geometry>
        <mesh filename="package://onrobot_rg2/collision/inner_knuckle.stl"/>
      </geometry>
    </collision>
  </link>

  <!-- Left inner finger -->
  <link name="left_inner_finger">
    <inertial>
      <origin xyz="0.0 0.0 0.0" rpy="0 0 0"/>
      <mass value="0.05"/>
      <inertia ixx="1.0E-03" ixy="1.0E-06" ixz="1.0E-06" iyy="1.0E-03" iyz="1.0E-06" izz="1.0E-03"/>
    </inertial>
    <visual>
      <origin xyz="0 0 0" rpy="0 0 0"/>
      <geometry>
        <mesh filename="package://onrobot_rg2/visual/inner_finger_visual.stl"/>
      </geometry>
      <material name="GripperBlack">
        <color rgba="0.1 0.1 0.1 1"/>
      </material>
    </visual>
    <collision>
      <origin xyz="0 0 0" rpy="0 0 0"/>
      <geometry>
        <mesh filename="package://onrobot_rg2/collision/inner_finger.stl"/>
      </geometry>
    </collision>
  </link>

  <!-- Left finger joint (primary actuated joint) -->
  <joint name="finger_joint" type="revolute">
    <origin xyz="0 -0.017178 0.125797" rpy="0 0 0"/>
    <parent link="onrobot_rg2_base_link"/>
    <child link="left_outer_knuckle"/>
    <axis xyz="-1 0 0"/>
    <limit lower="-0.558505" upper="0.785398" velocity="100.0" effort="1000"/>
  </joint>

  <!-- Left inner knuckle joint (mimics finger_joint) -->
  <joint name="left_inner_knuckle_joint" type="revolute">
    <origin xyz="0 -0.007678 0.142297" rpy="0 0 0"/>
    <parent link="onrobot_rg2_base_link"/>
    <child link="left_inner_knuckle"/>
    <axis xyz="1 0 0"/>
    <limit lower="-0.785398" upper="0.785398" velocity="100.0" effort="1000"/>
    <mimic joint="finger_joint" multiplier="-1" offset="0"/>
  </joint>

  <!-- Left inner finger joint (mimics finger_joint) -->
  <joint name="left_inner_finger_joint" type="revolute">
    <origin xyz="0 -0.039592 0.038177" rpy="0 0 0"/>
    <parent link="left_outer_knuckle"/>
    <child link="left_inner_finger"/>
    <axis xyz="1 0 0"/>
    <limit lower="-0.872665" upper="0.872665" velocity="100.0" effort="1000"/>
    <mimic joint="finger_joint" multiplier="1" offset="0"/>
  </joint>

  <!-- ===== Right finger ===== -->

  <!-- Right outer knuckle -->
  <link name="right_outer_knuckle">
    <inertial>
      <origin xyz="0.0 0.0 0.0" rpy="0 0 0"/>
      <mass value="0.05"/>
      <inertia ixx="1.0E-03" ixy="1.0E-06" ixz="1.0E-06" iyy="1.0E-03" iyz="1.0E-06" izz="1.0E-03"/>
    </inertial>
    <visual>
      <origin xyz="0 0 0" rpy="0 0 0"/>
      <geometry>
        <mesh filename="package://onrobot_rg2/visual/outer_knuckle_visual.stl"/>
      </geometry>
      <material name="GripperGrey">
        <color rgba="0.8 0.8 0.8 1"/>
      </material>
    </visual>
    <collision>
      <origin xyz="0 0 0" rpy="0 0 0"/>
      <geometry>
        <mesh filename="package://onrobot_rg2/collision/outer_knuckle.stl"/>
      </geometry>
    </collision>
  </link>

  <!-- Right inner knuckle -->
  <link name="right_inner_knuckle">
    <inertial>
      <origin xyz="0.0 0.0 0.0" rpy="0 0 0"/>
      <mass value="0.05"/>
      <inertia ixx="1.0E-03" ixy="1.0E-06" ixz="1.0E-06" iyy="1.0E-03" iyz="1.0E-06" izz="1.0E-03"/>
    </inertial>
    <visual>
      <origin xyz="0 0 0" rpy="0 0 0"/>
      <geometry>
        <mesh filename="package://onrobot_rg2/visual/inner_knuckle_visual.stl"/>
      </geometry>
      <material name="GripperGrey">
        <color rgba="0.8 0.8 0.8 1"/>
      </material>
    </visual>
    <collision>
      <origin xyz="0 0 0" rpy="0 0 0"/>
      <geometry>
        <mesh filename="package://onrobot_rg2/collision/inner_knuckle.stl"/>
      </geometry>
    </collision>
  </link>

  <!-- Right inner finger -->
  <link name="right_inner_finger">
    <inertial>
      <origin xyz="0.0 0.0 0.0" rpy="0 0 0"/>
      <mass value="0.05"/>
      <inertia ixx="1.0E-03" ixy="1.0E-06" ixz="1.0E-06" iyy="1.0E-03" iyz="1.0E-06" izz="1.0E-03"/>
    </inertial>
    <visual>
      <origin xyz="0 0 0" rpy="0 0 0"/>
      <geometry>
        <mesh filename="package://onrobot_rg2/visual/inner_finger_visual.stl"/>
      </geometry>
      <material name="GripperBlack">
        <color rgba="0.1 0.1 0.1 1"/>
      </material>
    </visual>
    <collision>
      <origin xyz="0 0 0" rpy="0 0 0"/>
      <geometry>
        <mesh filename="package://onrobot_rg2/collision/inner_finger.stl"/>
      </geometry>
    </collision>
  </link>

  <!-- Right outer knuckle joint (mimics finger_joint, mirrored) -->
  <joint name="right_outer_knuckle_joint" type="revolute">
    <origin xyz="0 0.017178 0.125797" rpy="0 0 3.141592653589793"/>
    <parent link="onrobot_rg2_base_link"/>
    <child link="right_outer_knuckle"/>
    <axis xyz="1 0 0"/>
    <limit lower="-0.785398" upper="0.785398" velocity="100.0" effort="1000"/>
    <mimic joint="finger_joint" multiplier="-1" offset="0"/>
  </joint>

  <!-- Right inner knuckle joint (mimics finger_joint) -->
  <joint name="right_inner_knuckle_joint" type="revolute">
    <origin xyz="0 0.007678 0.142297" rpy="0 0 3.141592653589793"/>
    <parent link="onrobot_rg2_base_link"/>
    <child link="right_inner_knuckle"/>
    <axis xyz="1 0 0"/>
    <limit lower="-0.785398" upper="0.785398" velocity="100.0" effort="1000"/>
    <mimic joint="finger_joint" multiplier="-1" offset="0"/>
  </joint>

  <!-- Right inner finger joint (mimics finger_joint) -->
  <joint name="right_inner_finger_joint" type="revolute">
    <origin xyz="0 -0.039592 0.038177" rpy="0 0 0"/>
    <parent link="right_outer_knuckle"/>
    <child link="right_inner_finger"/>
    <axis xyz="1 0 0"/>
    <limit lower="-0.872665" upper="0.872665" velocity="100.0" effort="1000"/>
    <mimic joint="finger_joint" multiplier="1" offset="0"/>
  </joint>

</robot>
